Traceback (most recent call last):
  File "/home/kwoksun2/anaconda3/lib/python3.8/site-packages/jupyter_cache/executors/utils.py", line 51, in single_nb_execution
    executenb(
  File "/home/kwoksun2/anaconda3/lib/python3.8/site-packages/nbclient/client.py", line 1204, in execute
    return NotebookClient(nb=nb, resources=resources, km=km, **kwargs).execute()
  File "/home/kwoksun2/anaconda3/lib/python3.8/site-packages/nbclient/util.py", line 84, in wrapped
    return just_run(coro(*args, **kwargs))
  File "/home/kwoksun2/anaconda3/lib/python3.8/site-packages/nbclient/util.py", line 62, in just_run
    return loop.run_until_complete(coro)
  File "/home/kwoksun2/anaconda3/lib/python3.8/asyncio/base_events.py", line 616, in run_until_complete
    return future.result()
  File "/home/kwoksun2/anaconda3/lib/python3.8/site-packages/nbclient/client.py", line 663, in async_execute
    await self.async_execute_cell(
  File "/home/kwoksun2/anaconda3/lib/python3.8/site-packages/nbclient/client.py", line 965, in async_execute_cell
    await self._check_raise_for_error(cell, cell_index, exec_reply)
  File "/home/kwoksun2/anaconda3/lib/python3.8/site-packages/nbclient/client.py", line 862, in _check_raise_for_error
    raise CellExecutionError.from_cell_and_msg(cell, exec_reply_content)
nbclient.exceptions.CellExecutionError: An error occurred while executing the following cell:
------------------
import pyximport
import numpy as np
solver_name = "simpleNetwork"

pyximport.install(
    setup_args={"include_dirs":np.get_include()},
    reload_support=True, 
    inplace=True, 
    language_level=3
)

simple_solver_run = pyximport.load_module(
    f"{solver_name}_solver_run",
    f"{solver_name}_solver_run.pyx",
    build_inplace = True, 
    pyxbuild_dir = "_dengo_temp", 
    )
------------------

[0;31m---------------------------------------------------------------------------[0m
[0;31mImportError[0m                               Traceback (most recent call last)
File [0;32m~/anaconda3/lib/python3.8/site-packages/pyximport/pyximport.py:216[0m, in [0;36mload_module[0;34m(name, pyxfilename, pyxbuild_dir, is_package, build_inplace, language_level, so_path)[0m
[1;32m    214[0m     so_path [38;5;241m=[39m build_module(module_name, pyxfilename, pyxbuild_dir,
[1;32m    215[0m                            inplace[38;5;241m=[39mbuild_inplace, language_level[38;5;241m=[39mlanguage_level)
[0;32m--> 216[0m mod [38;5;241m=[39m [43mimp[49m[38;5;241;43m.[39;49m[43mload_dynamic[49m[43m([49m[43mname[49m[43m,[49m[43m [49m[43mso_path[49m[43m)[49m
[1;32m    217[0m [38;5;28;01mif[39;00m is_package [38;5;129;01mand[39;00m [38;5;129;01mnot[39;00m [38;5;28mhasattr[39m(mod, [38;5;124m'[39m[38;5;124m__path__[39m[38;5;124m'[39m):

File [0;32m~/anaconda3/lib/python3.8/imp.py:342[0m, in [0;36mload_dynamic[0;34m(name, path, file)[0m
[1;32m    340[0m spec [38;5;241m=[39m importlib[38;5;241m.[39mmachinery[38;5;241m.[39mModuleSpec(
[1;32m    341[0m     name[38;5;241m=[39mname, loader[38;5;241m=[39mloader, origin[38;5;241m=[39mpath)
[0;32m--> 342[0m [38;5;28;01mreturn[39;00m [43m_load[49m[43m([49m[43mspec[49m[43m)[49m

File [0;32m<frozen importlib._bootstrap>:702[0m, in [0;36m_load[0;34m(spec)[0m

File [0;32m<frozen importlib._bootstrap>:657[0m, in [0;36m_load_unlocked[0;34m(spec)[0m

File [0;32m<frozen importlib._bootstrap>:556[0m, in [0;36mmodule_from_spec[0;34m(spec)[0m

File [0;32m<frozen importlib._bootstrap_external>:1101[0m, in [0;36mcreate_module[0;34m(self, spec)[0m

File [0;32m<frozen importlib._bootstrap>:219[0m, in [0;36m_call_with_frames_removed[0;34m(f, *args, **kwds)[0m

[0;31mImportError[0m: /mnt/gv0/homes/kwoksun2/dengo-merge/cookbook/tutorial/buildingblocks/simpleNetwork_solver_run.cpython-38-x86_64-linux-gnu.so.reload1: undefined symbol: _Z18setup_cvode_solverPFidP17_generic_N_VectorS0_PvEPFidS0_S0_P18_generic_SUNMatrixS1_S0_S0_S0_EiP18simpleNetwork_dataP24_generic_SUNLinearSolverS5_S0_dS0_

During handling of the above exception, another exception occurred:

[0;31mImportError[0m                               Traceback (most recent call last)
Input [0;32mIn [2][0m, in [0;36m<cell line: 12>[0;34m()[0m
[1;32m      3[0m solver_name [38;5;241m=[39m [38;5;124m"[39m[38;5;124msimpleNetwork[39m[38;5;124m"[39m
[1;32m      5[0m pyximport[38;5;241m.[39minstall(
[1;32m      6[0m     setup_args[38;5;241m=[39m{[38;5;124m"[39m[38;5;124minclude_dirs[39m[38;5;124m"[39m:np[38;5;241m.[39mget_include()},
[1;32m      7[0m     reload_support[38;5;241m=[39m[38;5;28;01mTrue[39;00m, 
[1;32m      8[0m     inplace[38;5;241m=[39m[38;5;28;01mTrue[39;00m, 
[1;32m      9[0m     language_level[38;5;241m=[39m[38;5;241m3[39m
[1;32m     10[0m )
[0;32m---> 12[0m simple_solver_run [38;5;241m=[39m [43mpyximport[49m[38;5;241;43m.[39;49m[43mload_module[49m[43m([49m
[1;32m     13[0m [43m    [49m[38;5;124;43mf[39;49m[38;5;124;43m"[39;49m[38;5;132;43;01m{[39;49;00m[43msolver_name[49m[38;5;132;43;01m}[39;49;00m[38;5;124;43m_solver_run[39;49m[38;5;124;43m"[39;49m[43m,[49m
[1;32m     14[0m [43m    [49m[38;5;124;43mf[39;49m[38;5;124;43m"[39;49m[38;5;132;43;01m{[39;49;00m[43msolver_name[49m[38;5;132;43;01m}[39;49;00m[38;5;124;43m_solver_run.pyx[39;49m[38;5;124;43m"[39;49m[43m,[49m
[1;32m     15[0m [43m    [49m[43mbuild_inplace[49m[43m [49m[38;5;241;43m=[39;49m[43m [49m[38;5;28;43;01mTrue[39;49;00m[43m,[49m[43m [49m
[1;32m     16[0m [43m    [49m[43mpyxbuild_dir[49m[43m [49m[38;5;241;43m=[39;49m[43m [49m[38;5;124;43m"[39;49m[38;5;124;43m_dengo_temp[39;49m[38;5;124;43m"[39;49m[43m,[49m[43m [49m
[1;32m     17[0m [43m    [49m[43m)[49m

File [0;32m~/anaconda3/lib/python3.8/site-packages/pyximport/pyximport.py:231[0m, in [0;36mload_module[0;34m(name, pyxfilename, pyxbuild_dir, is_package, build_inplace, language_level, so_path)[0m
[1;32m    228[0m exc [38;5;241m=[39m [38;5;167;01mImportError[39;00m([38;5;124m"[39m[38;5;124mBuilding module [39m[38;5;132;01m%s[39;00m[38;5;124m failed: [39m[38;5;132;01m%s[39;00m[38;5;124m"[39m [38;5;241m%[39m (
[1;32m    229[0m     name, traceback[38;5;241m.[39mformat_exception_only([38;5;241m*[39msys[38;5;241m.[39mexc_info()[:[38;5;241m2[39m])))
[1;32m    230[0m [38;5;28;01mif[39;00m sys[38;5;241m.[39mversion_info[[38;5;241m0[39m] [38;5;241m>[39m[38;5;241m=[39m [38;5;241m3[39m:
[0;32m--> 231[0m     [38;5;28;01mraise[39;00m exc[38;5;241m.[39mwith_traceback(tb)
[1;32m    232[0m [38;5;28;01melse[39;00m:
[1;32m    233[0m     exec([38;5;124m"[39m[38;5;124mraise exc, None, tb[39m[38;5;124m"[39m, {[38;5;124m'[39m[38;5;124mexc[39m[38;5;124m'[39m: exc, [38;5;124m'[39m[38;5;124mtb[39m[38;5;124m'[39m: tb})

File [0;32m~/anaconda3/lib/python3.8/site-packages/pyximport/pyximport.py:216[0m, in [0;36mload_module[0;34m(name, pyxfilename, pyxbuild_dir, is_package, build_inplace, language_level, so_path)[0m
[1;32m    213[0m         module_name [38;5;241m=[39m name
[1;32m    214[0m     so_path [38;5;241m=[39m build_module(module_name, pyxfilename, pyxbuild_dir,
[1;32m    215[0m                            inplace[38;5;241m=[39mbuild_inplace, language_level[38;5;241m=[39mlanguage_level)
[0;32m--> 216[0m mod [38;5;241m=[39m [43mimp[49m[38;5;241;43m.[39;49m[43mload_dynamic[49m[43m([49m[43mname[49m[43m,[49m[43m [49m[43mso_path[49m[43m)[49m
[1;32m    217[0m [38;5;28;01mif[39;00m is_package [38;5;129;01mand[39;00m [38;5;129;01mnot[39;00m [38;5;28mhasattr[39m(mod, [38;5;124m'[39m[38;5;124m__path__[39m[38;5;124m'[39m):
[1;32m    218[0m     mod[38;5;241m.[39m__path__ [38;5;241m=[39m [os[38;5;241m.[39mpath[38;5;241m.[39mdirname(so_path)]

File [0;32m~/anaconda3/lib/python3.8/imp.py:342[0m, in [0;36mload_dynamic[0;34m(name, path, file)[0m
[1;32m    338[0m [38;5;66;03m# Issue #24748: Skip the sys.modules check in _load_module_shim;[39;00m
[1;32m    339[0m [38;5;66;03m# always load new extension[39;00m
[1;32m    340[0m spec [38;5;241m=[39m importlib[38;5;241m.[39mmachinery[38;5;241m.[39mModuleSpec(
[1;32m    341[0m     name[38;5;241m=[39mname, loader[38;5;241m=[39mloader, origin[38;5;241m=[39mpath)
[0;32m--> 342[0m [38;5;28;01mreturn[39;00m [43m_load[49m[43m([49m[43mspec[49m[43m)[49m

File [0;32m<frozen importlib._bootstrap>:702[0m, in [0;36m_load[0;34m(spec)[0m

File [0;32m<frozen importlib._bootstrap>:657[0m, in [0;36m_load_unlocked[0;34m(spec)[0m

File [0;32m<frozen importlib._bootstrap>:556[0m, in [0;36mmodule_from_spec[0;34m(spec)[0m

File [0;32m<frozen importlib._bootstrap_external>:1101[0m, in [0;36mcreate_module[0;34m(self, spec)[0m

File [0;32m<frozen importlib._bootstrap>:219[0m, in [0;36m_call_with_frames_removed[0;34m(f, *args, **kwds)[0m

[0;31mImportError[0m: Building module simpleNetwork_solver_run failed: ['ImportError: /mnt/gv0/homes/kwoksun2/dengo-merge/cookbook/tutorial/buildingblocks/simpleNetwork_solver_run.cpython-38-x86_64-linux-gnu.so.reload1: undefined symbol: _Z18setup_cvode_solverPFidP17_generic_N_VectorS0_PvEPFidS0_S0_P18_generic_SUNMatrixS1_S0_S0_S0_EiP18simpleNetwork_dataP24_generic_SUNLinearSolverS5_S0_dS0_\n']
ImportError: Building module simpleNetwork_solver_run failed: ['ImportError: /mnt/gv0/homes/kwoksun2/dengo-merge/cookbook/tutorial/buildingblocks/simpleNetwork_solver_run.cpython-38-x86_64-linux-gnu.so.reload1: undefined symbol: _Z18setup_cvode_solverPFidP17_generic_N_VectorS0_PvEPFidS0_S0_P18_generic_SUNMatrixS1_S0_S0_S0_EiP18simpleNetwork_dataP24_generic_SUNLinearSolverS5_S0_dS0_\n']

